Workbook

Sheet Read Me
B2: AIP Library — Global Source Inventory & Rollout Tracker
B3: Working document — built from the team-supplied AIP source list, classified and structured for a region-wise, free-access-first rollout.
B6: WHAT THIS WORKBOOK IS
B9: SHEETS IN THIS WORKBOOK
B10: Summary Dashboard | C10: Top-line counts: coverage, access-type split, rollout phase split. Updates automatically as you edit Master Inventory.
B11: Region Rollout Plan | C11: Recommended region sequencing with rationale, and per-region free/paid/needs-research counts.
B12: Shared Ingestion Sources | C12: The highest-leverage rows — single connectors that cover multiple countries at once (e.g. one ASECNA scraper = 18 African states). Build these first.
B13: Master Inventory | C13: The full working list — every country, its source URL, heuristic access classification, rollout phase, and editable Status/Owner/Notes columns for your team to fill in as you verify each site.
B14: Needs Research | C14: Action list: countries with no source on file, or with links that look internal/restricted rather than official public AIS sites.
B16: ACCESS TYPE LEGEND (Master Inventory column F)
B17: FREE (Verified) | C17: I independently confirmed this is a free, official public AIS/eAIP site.
B18: LIKELY FREE (Unverified) | C18: Domain pattern matches the global default norm for public eAIP sites (gov/ANSP domain, no login wall detected). Not individually checked — verify before build.
B19: LOGIN REQUIRED - VERIFY | C19: URL points to a login/account/extranet gate. Could be free registration (like EUROCONTROL EAD Basic) or a paid subscription — confirm which before building a connector.
B20: PAID | C20: Confirmed commercial/subscription source (e.g. AeroPath's storefront for several Pacific Island states).
B21: RESTRICTED / INTERNAL - VERIFY | C21: The link looks like an internal file share (SharePoint/OneDrive) rather than an official public AIS site — likely needs replacing with the real state source.
B22: NO SOURCE FOUND | C22: No URL was supplied for this state — needs research from scratch.
B24: IMPORTANT CAVEAT
B27: HOW TO USE

Sheet Summary Dashboard
B2: AIP Library — Coverage Dashboard
B3: Live counts pulled from Master Inventory — updates automatically as Status/data is edited.
B6: Total states tracked | D6: =COUNTA('Master Inventory'!B2:B221) -> 220
B7: Free or Likely-Free (combined) | D7: =COUNTIF('Master Inventory'!F2:F221,"FREE (Verified)")+COUNTIF('Master Inventory'!F2:F221,"LIKELY FREE (Unverified)") -> 196
B8: Paid (skip for now) | D8: =COUNTIF('Master Inventory'!F2:F221,"PAID") -> 8
B9: Needs research (no source / restricted link) | D9: =COUNTIF('Master Inventory'!F2:F221,"NO SOURCE FOUND")+COUNTIF('Master Inventory'!F2:F221,"RESTRICTED / INTERNAL - VERIFY") -> 12
B10: Login-gated, access model unconfirmed | D10: =COUNTIF('Master Inventory'!F2:F221,"LOGIN REQUIRED - VERIFY") -> 4
B13: Access Type Breakdown
B14: Access Type | C14: Count
B15: FREE (Verified) | C15: =COUNTIF('Master Inventory'!F2:F221,"FREE (Verified)") -> 62
B16: LIKELY FREE (Unverified) | C16: =COUNTIF('Master Inventory'!F2:F221,"LIKELY FREE (Unverified)") -> 134
B17: LOGIN REQUIRED - VERIFY | C17: =COUNTIF('Master Inventory'!F2:F221,"LOGIN REQUIRED - VERIFY") -> 4
B18: PAID | C18: =COUNTIF('Master Inventory'!F2:F221,"PAID") -> 8
B19: RESTRICTED / INTERNAL - VERIFY | C19: =COUNTIF('Master Inventory'!F2:F221,"RESTRICTED / INTERNAL - VERIFY") -> 7
B20: NO SOURCE FOUND | C20: =COUNTIF('Master Inventory'!F2:F221,"NO SOURCE FOUND") -> 5
B23: Rollout Phase Breakdown
B24: Rollout Phase | C24: Count
B25: Phase 1 - Free | C25: =COUNTIF('Master Inventory'!H2:H221,"Phase 1 - Free") -> 62
B26: Phase 2 - Verify | C26: =COUNTIF('Master Inventory'!H2:H221,"Phase 2 - Verify") -> 138
B27: Phase 3 - Paid (Skip for now) | C27: =COUNTIF('Master Inventory'!H2:H221,"Phase 3 - Paid (Skip for now)") -> 8
B28: Phase X - Unresolved | C28: =COUNTIF('Master Inventory'!H2:H221,"Phase X - Unresolved") -> 12

Sheet Region Rollout Plan
B2: Recommended Region-by-Region Rollout Sequence
B3: Default sequencing — reorder the Sequence column to match your own route-network priorities.
A5: Sequence | B5: Region | C5: Total States | D5: Free (Verified) | E5: Likely Free (Unverified) | F5: Paid | G5: Needs Research | H5: % Free/Likely-Free | I5: Rationale
A6: 1 | B6: NORTH & CENTRAL AMERICA | C6: =COUNTIF('Master Inventory'!A:A,B6) -> 37 | D6: =COUNTIFS('Master Inventory'!A:A,B6,'Master Inventory'!F:F,"FREE (Verified)") -> 26 | E6: =COUNTIFS('Master Inventory'!A:A,B6,'Master Inventory'!F:F,"LIKELY FREE (Unverified)") -> 9 | F6: =COUNTIFS('Master Inventory'!A:A,B6,'Master Inventory'!F:F,"PAID") -> 0 | G6: =COUNTIFS('Master Inventory'!A:A,B6,'Master Inventory'!F:F,"NO SOURCE FOUND")+COUNTIFS('Master Inventory'!A:A,B6,'Master Inventory'!F:F,"RESTRICTED / INTERNAL - VERIFY") -> 1 | H6: =(D6+E6)/C6 -> 0.94594595 | I6: Highest confirmed-free ratio, includes 3 mega-leverage shared connectors (T&T CAA x10, COCESNA x6, Dutch Caribbean ANSP x6) plus US/Canada/Mexico. Fastest, highest-confidence region to start with.
A7: 2 | B7: EUROPE | C7: =COUNTIF('Master Inventory'!A:A,B7) -> 54 | D7: =COUNTIFS('Master Inventory'!A:A,B7,'Master Inventory'!F:F,"FREE (Verified)") -> 9 | E7: =COUNTIFS('Master Inventory'!A:A,B7,'Master Inventory'!F:F,"LIKELY FREE (Unverified)") -> 44 | F7: =COUNTIFS('Master Inventory'!A:A,B7,'Master Inventory'!F:F,"PAID") -> 0 | G7: =COUNTIFS('Master Inventory'!A:A,B7,'Master Inventory'!F:F,"NO SOURCE FOUND")+COUNTIFS('Master Inventory'!A:A,B7,'Master Inventory'!F:F,"RESTRICTED / INTERNAL - VERIFY") -> 0 | H7: =(D7+E7)/C7 -> 0.98148148 | I7: Highest overall free ratio (98%) and the highest operational value for most flight-ops businesses. Mostly standardized under EUROCONTROL eAIP conventions; individual sites need verification but few red flags.
A8: 3 | B8: AFRICA | C8: =COUNTIF('Master Inventory'!A:A,B8) -> 57 | D8: =COUNTIFS('Master Inventory'!A:A,B8,'Master Inventory'!F:F,"FREE (Verified)") -> 20 | E8: =COUNTIFS('Master Inventory'!A:A,B8,'Master Inventory'!F:F,"LIKELY FREE (Unverified)") -> 28 | F8: =COUNTIFS('Master Inventory'!A:A,B8,'Master Inventory'!F:F,"PAID") -> 0 | G8: =COUNTIFS('Master Inventory'!A:A,B8,'Master Inventory'!F:F,"NO SOURCE FOUND")+COUNTIFS('Master Inventory'!A:A,B8,'Master Inventory'!F:F,"RESTRICTED / INTERNAL - VERIFY") -> 8 | H8: =(D8+E8)/C8 -> 0.84210526 | I8: Largest state count, but the ASECNA block alone (2 connectors) covers 18 states — build that first for outsized ROI. Remaining ~39 states need individual verification; expect some genuine gaps (not every state maintains a digital AIP).
A9: 4 | B9: MIDDLE EAST | C9: =COUNTIF('Master Inventory'!A:A,B9) -> 15 | D9: =COUNTIFS('Master Inventory'!A:A,B9,'Master Inventory'!F:F,"FREE (Verified)") -> 0 | E9: =COUNTIFS('Master Inventory'!A:A,B9,'Master Inventory'!F:F,"LIKELY FREE (Unverified)") -> 14 | F9: =COUNTIFS('Master Inventory'!A:A,B9,'Master Inventory'!F:F,"PAID") -> 0 | G9: =COUNTIFS('Master Inventory'!A:A,B9,'Master Inventory'!F:F,"NO SOURCE FOUND")+COUNTIFS('Master Inventory'!A:A,B9,'Master Inventory'!F:F,"RESTRICTED / INTERNAL - VERIFY") -> 1 | H9: =(D9+E9)/C9 -> 0.93333333 | I9: Smaller set (15 states), high overflight/routing value for international operators.
A10: 5 | B10: ASIA & PACIFIC | C10: =COUNTIF('Master Inventory'!A:A,B10) -> 42 | D10: =COUNTIFS('Master Inventory'!A:A,B10,'Master Inventory'!F:F,"FREE (Verified)") -> 5 | E10: =COUNTIFS('Master Inventory'!A:A,B10,'Master Inventory'!F:F,"LIKELY FREE (Unverified)") -> 28 | F10: =COUNTIFS('Master Inventory'!A:A,B10,'Master Inventory'!F:F,"PAID") -> 8 | G10: =COUNTIFS('Master Inventory'!A:A,B10,'Master Inventory'!F:F,"NO SOURCE FOUND")+COUNTIFS('Master Inventory'!A:A,B10,'Master Inventory'!F:F,"RESTRICTED / INTERNAL - VERIFY") -> 1 | H10: =(D10+E10)/C10 -> 0.78571429 | I10: Contains major world markets (India, China, Japan, Singapore, Australia, Indonesia, Malaysia, Thailand, Vietnam, South Korea, Philippines) worth prioritizing — but also the only region with confirmed paid sources (8 Pacific micro-states via one commercial reseller). Do the major markets first, defer the paid Pacific islands.
A11: 6 | B11: SOUTH AMERICA | C11: =COUNTIF('Master Inventory'!A:A,B11) -> 15 | D11: =COUNTIFS('Master Inventory'!A:A,B11,'Master Inventory'!F:F,"FREE (Verified)") -> 2 | E11: =COUNTIFS('Master Inventory'!A:A,B11,'Master Inventory'!F:F,"LIKELY FREE (Unverified)") -> 11 | F11: =COUNTIFS('Master Inventory'!A:A,B11,'Master Inventory'!F:F,"PAID") -> 0 | G11: =COUNTIFS('Master Inventory'!A:A,B11,'Master Inventory'!F:F,"NO SOURCE FOUND")+COUNTIFS('Master Inventory'!A:A,B11,'Master Inventory'!F:F,"RESTRICTED / INTERNAL - VERIFY") -> 1 | H11: =(D11+E11)/C11 -> 0.86666667 | I11: Smallest region by count (15 states), moderate priority.

Sheet Shared Ingestion Sources
B2: High-Leverage Sources — Build Once, Cover Many States
B3: One connector/scraper against each of these domains covers every listed country. Build these first for maximum coverage per engineering hour.
A5: Domain (Ingestion Source) | B5: Region | C5: # States Covered | D5: Access Type | E5: States Covered | F5: Build Priority
A6: ais.asecna.aero | B6: AFRICA | C6: 16 | D6: FREE (Verified) | E6: Benin, Cameroon, Central African Republic, Chad, Comoros, Congo (Brazzville), Equatorial Guinea, Gabon, Guinea-Bissau, Ivory Coast, Madagascar, Mali, Mauritania, Niger, Senegal, Togo | F6: Build First (Tier 1)
A7: caa.gov.tt | B7: NORTH & CENTRAL AMERICA | C7: 10 | D7: FREE (Verified) | E7: Anguilla, Antigua And Barbuda, Dominica, Grenada, Montserrat, Saint Christopher And Nev, Saint Lucia, Saint Vincent And Grenadines, Trinidad And Tobago, Uk Virgin Islands | F7: Build First (Tier 1)
A8: shop.aeropath.aero | B8: ASIA & PACIFIC | C8: 8 | D8: PAID | E8: Kiribati, Nauru, Niue, Samoa, Solomon Islands, Tonga, Tuvalu, Vanutau | F8: Skip for now (Paid)
A9: www.cocesna.org | B9: NORTH & CENTRAL AMERICA | C9: 6 | D9: FREE (Verified) | E9: Belize, Costa Rica, El Salvador, Guatemala, Honduras, Nicaragua | F9: Build First (Tier 1)
A10: dc-ansp.org | B10: NORTH & CENTRAL AMERICA | C10: 6 | D10: FREE (Verified) | E10: Aruba (Netherlands), Bonaire Saba St Eustatius, Curacao, Saba (Netherlands), Saint Eustatius, Saint Maarten (Netherlands) | F10: Build First (Tier 1)
A11: sabrenow.sharepoint.com | B11: AFRICA | C11: 3 | D11: RESTRICTED / INTERNAL - VERIFY | E11: Burundi, Eritrea, Malawi | F11: Fix link first (see Needs Research)
A12: www.caica.ru | B12: EUROPE | C12: 3 | D12: LIKELY FREE (Unverified) | E12: Russian Federation, Tajikistan, Turkmenistan | F12: Build Early (Tier 2)
A13: www.sia.aviation-civile.gouv.fr | B13: ASIA & PACIFIC | C13: 3 | D13: FREE (Verified) | E13: French Polinesia, New Caledonia (France), Wallis And Futana Islands | F13: Build Early (Tier 2)
A14: www.faa.gov | B14: NORTH & CENTRAL AMERICA | C14: 3 | D14: FREE (Verified) | E14: Puerto Rico (Us), United States, Us Virgin Islands | F14: Build Early (Tier 2)
A15: aim.naviair.dk | B15: EUROPE | C15: 3 | D15: FREE (Verified) | E15: Denmark, Faroe Islands, Greenland | F15: Build Early (Tier 2)
A16: aip.enaire.es | B16: EUROPE | C16: 2 | D16: LIKELY FREE (Unverified) | E16: Gibraltar, Spain (Canary Islands) | F16: Build Early (Tier 2)
A17: aim.asecna.aero | B17: AFRICA | C17: 2 | D17: FREE (Verified) | E17: Burkina Faso, Rwanda | F17: Build Early (Tier 2)
... A22: ops.skeyes.be | B22: EUROPE | C22: 2 | D22: FREE (Verified) | E22: Belgium, Luxembourg | F22: Build Early (Tier 2)

Sheet Master Inventory
A1: Region | B1: Country | C1: ICAO Code | D1: eAIP / AIS URL | E1: Corrected URL (if flagged) | F1: Access Type | G1: Heuristic Reasoning | H1: Rollout Phase | I1: Region Priority Rank | J1: States Sharing This Source | K1: Status | L1: Owner | M1: Last Checked | N1: Notes
A2: NORTH & CENTRAL AMERICA | B2: Anguilla | C2: TQ | D2: http://caa.gov.tt/ | F2: FREE (Verified) | G2: Confirmed via direct check of the official AIS/ANSP site | H2: Phase 1 - Free | I2: 1 | J2: 10 | K2: Not Started
A3: NORTH & CENTRAL AMERICA | B3: Antigua And Barbuda | C3: TA | D3: http://caa.gov.tt/ | F3: FREE (Verified) | G3: Confirmed via direct check of the official AIS/ANSP site | H3: Phase 1 - Free | I3: 1 | J3: 10 | K3: Not Started
A4: NORTH & CENTRAL AMERICA | B4: Aruba (Netherlands) | C4: TN | D4: https://dc-ansp.org/eAIS/eaip-dutch-caribbean/ | F4: FREE (Verified) | G4: Confirmed via direct check of the official AIS/ANSP site | H4: Phase 1 - Free | I4: 1 | J4: 6 | K4: Not Started
A5: NORTH & CENTRAL AMERICA | B5: Bahamas | C5: MY | D5: https://bansabahamas.com/aip.html | F5: LIKELY FREE (Unverified) | G5: No paid/restricted signal detected — defaulting to global norm (most state eAIP sites are free to view); not individually confirmed | H5: Phase 2 - Verify | I5: 1 | J5: 1 | K5: Not Started
A6: NORTH & CENTRAL AMERICA | B6: Barbados | C6: TB | D6: http://bcad.gov.bb/eAIP/bcad/index.php | F6: LIKELY FREE (Unverified) | G6: Government / ANSP / civil aviation authority domain pattern — matches the global default norm of free public eAIP access | H6: Phase 2 - Verify | I6: 1 | J6: 1 | K6: Not Started
A7: NORTH & CENTRAL AMERICA | B7: Belize | C7: MZ | D7: https://www.cocesna.org/index.php?id=14 | F7: FREE (Verified) | G7: Confirmed via direct check of the official AIS/ANSP site | H7: Phase 1 - Free | I7: 1 | J7: 6 | K7: Not Started
A8: NORTH & CENTRAL AMERICA | B8: Bermuda | C8: TX | D8: https://www.airportauthority.bm/ais/aeronautical-info-publication.html | F8: LIKELY FREE (Unverified) | G8: No paid/restricted signal detected — defaulting to global norm (most state eAIP sites are free to view); not individually confirmed | H8: Phase 2 - Verify | I8: 1 | J8: 1 | K8: Not Started
A9: NORTH & CENTRAL AMERICA | B9: Bonaire Saba St Eustatius | C9: TN | D9: https://dc-ansp.org/eAIS/eaip-dutch-caribbean/ | F9: FREE (Verified) | G9: Confirmed via direct check of the official AIS/ANSP site | H9: Phase 1 - Free | I9: 1 | J9: 6 | K9: Not Started
A10: NORTH & CENTRAL AMERICA | B10: Canada | C10: CY & CZ | D10: https://navcanada.sharepoint.com/sites/Extranet | E10: https://www.navcanada.ca/en/aeronautical-information/aip-canada.aspx | F10: RESTRICTED / INTERNAL - VERIFY | G10: Cloud file-share link, not an official public AIS domain — likely wrong/internal link | H10: Phase X - Unresolved | I10: 1 | J10: 1 | K10: Not Started
A11: NORTH & CENTRAL AMERICA | B11: Cayman Islands | C11: MW | D11: https://www.caymanairports.com/aeronautical-information-publication/ | F11: LIKELY FREE (Unverified) | G11: No paid/restricted signal detected — defaulting to global norm (most state eAIP sites are free to view); not individually confirmed | H11: Phase 2 - Verify | I11: 1 | J11: 1 | K11: Not Started
A12: NORTH & CENTRAL AMERICA | B12: Costa Rica | C12: MR | D12: https://www.cocesna.org/index.php?id=14 | F12: FREE (Verified) | G12: Confirmed via direct check of the official AIS/ANSP site | H12: Phase 1 - Free | I12: 1 | J12: 6 | K12: Not Started
A13: NORTH & CENTRAL AMERICA | B13: Cuba | C13: MU | D13: http://aismet.avianet.cu/html/index.html | F13: LIKELY FREE (Unverified) | G13: No paid/restricted signal detected — defaulting to global norm (most state eAIP sites are free to view); not individually confirmed | H13: Phase 2 - Verify | I13: 1 | J13: 1 | K13: Not Started
A14: NORTH & CENTRAL AMERICA | B14: Curacao | C14: TN | D14: https://dc-ansp.org/eAIS/eaip-dutch-caribbean/ | F14: FREE (Verified) | G14: Confirmed via direct check of the official AIS/ANSP site | H14: Phase 1 - Free | I14: 1 | J14: 6 | K14: Not Started
A15: NORTH & CENTRAL AMERICA | B15: Dominica | C15: TD | D15: http://caa.gov.tt/ | F15: FREE (Verified) | G15: Confirmed via direct check of the official AIS/ANSP site | H15: Phase 1 - Free | I15: 1 | J15: 10 | K15: Not Started
A16: NORTH & CENTRAL AMERICA | B16: Dominican Republic | C16: MD | D16: https://aip.sna.gob.do/ | F16: LIKELY FREE (Unverified) | G16: Government / ANSP / civil aviation authority domain pattern — matches the global default norm of free public eAIP access | H16: Phase 2 - Verify | I16: 1 | J16: 1 | K16: Not Started
A17: NORTH & CENTRAL AMERICA | B17: El Salvador | C17: MS | D17: https://www.cocesna.org/index.php?id=14 | F17: FREE (Verified) | G17: Confirmed via direct check of the official AIS/ANSP site | H17: Phase 1 - Free | I17: 1 | J17: 6 | K17: Not Started
A18: NORTH & CENTRAL AMERICA | B18: French Antilles(Guadeloupe) | C18: TF | D18: http://www.sia.aviation-civile.gouv.fr/ | F18: FREE (Verified) | G18: Confirmed via direct check of the official AIS/ANSP site | H18: Phase 1 - Free | I18: 1 | J18: 9 | K18: Not Started
A19: NORTH & CENTRAL AMERICA | B19: Grenada | C19: TG | D19: http://caa.gov.tt/ | F19: FREE (Verified) | G19: Confirmed via direct check of the official AIS/ANSP site | H19: Phase 1 - Free | I19: 1 | J19: 10 | K19: Not Started
A20: NORTH & CENTRAL AMERICA | B20: Guatemala | C20: MG | D20: https://www.cocesna.org/index.php?id=14 | F20: FREE (Verified) | G20: Confirmed via direct check of the official AIS/ANSP site | H20: Phase 1 - Free | I20: 1 | J20: 6 | K20: Not Started
A21: NORTH & CENTRAL AMERICA | B21: Haiti | C21: MT | D21: https://ofnac.gouv.ht/index.php/amendment/ | F21: LIKELY FREE (Unverified) | G21: Government / ANSP / civil aviation authority domain pattern — matches the global default norm of free public eAIP access | H21: Phase 2 - Verify | I21: 1 | J21: 1 | K21: Not Started
A22: NORTH & CENTRAL AMERICA | B22: Honduras | C22: MH | D22: https://www.cocesna.org/index.php?id=14 | F22: FREE (Verified) | G22: Confirmed via direct check of the official AIS/ANSP site | H22: Phase 1 - Free | I22: 1 | J22: 6 | K22: Not Started
... A115: AFRICA | B115: Cape Verde Islands | C115: GV | D115: https://ais.asa.cv/ | F115: LIKELY FREE (Unverified) | G115: No paid/restricted signal detected — defaulting to global norm (most state eAIP sites are free to view); not individually confirmed | H115: Phase 2 - Verify | I115: 3 | J115: 1 | K115: Not Started
A116: AFRICA | B116: Congo (Kinshasa) | C116: FZ | F116: NO SOURCE FOUND | G116: No URL on file — needs research from scratch | H116: Phase X - Unresolved | I116: 3 | J116: 0 | K116: Not Started
A117: AFRICA | B117: Cueta And Melilla (Spain) | C117: GE | D117: https://www.enaire.es/services/AIS/AIP | F117: LIKELY FREE (Unverified) | G117: No paid/restricted signal detected — defaulting to global norm (most state eAIP sites are free to view); not individually confirmed | H117: Phase 2 - Verify | I117: 3 | J117: 1 | K117: Not Started
A118: AFRICA | B118: Djibouti | C118: HD | D118: https://djibaviationcivile.com/Circulaires?id=5f537098522dae004424ab1a | F118: LIKELY FREE (Unverified) | G118: Government / ANSP / civil aviation authority domain pattern — matches the global default norm of free public eAIP access | H118: Phase 2 - Verify | I118: 3 | J118: 1 | K118: Not Started
A119: AFRICA | B119: Egypt | C119: HE | D119: http://www.nansceg.net/ais.html | F119: LIKELY FREE (Unverified) | G119: No paid/restricted signal detected — defaulting to global norm (most state eAIP sites are free to view); not individually confirmed | H119: Phase 2 - Verify | I119: 3 | J119: 1 | K119: Not Started
A120: AFRICA | B120: Eritrea | C120: HH | D120: https://sabrenow.sharepoint.com/teams/ACD/FLT/FPM/dataservices/Test/Forms/AllItems.aspx | F120: RESTRICTED / INTERNAL - VERIFY | G120: Cloud file-share link, not an official public AIS domain — likely wrong/internal link | H120: Phase X - Unresolved | I120: 3 | J120: 5 | K120: Not Started
A121: AFRICA | B121: Eswatini | C121: FD | F121: NO SOURCE FOUND | G121: No URL on file — needs research from scratch | H121: Phase X - Unresolved | I121: 3 | J121: 0 | K121: Not Started
A122: AFRICA | B122: Ethiopia | C122: HA | F122: NO SOURCE FOUND | G122: No URL on file — needs research from scratch | H122: Phase X - Unresolved | I122: 3 | J122: 0 | K122: Not Started
A123: AFRICA | B123: Gambia | C123: GB | D123: https://eaip.gcaa.aero/eaip-gambia/html/historic/history.html | F123: LIKELY FREE (Unverified) | G123: Government / ANSP / civil aviation authority domain pattern — matches the global default norm of free public eAIP access | H123: Phase 2 - Verify | I123: 3 | J123: 1 | K123: Not Started
A124: AFRICA | B124: Ghana | C124: DG | D124: http://www.gcaa.com.gh/extweb/index.php/home | F124: LIKELY FREE (Unverified) | G124: Government / ANSP / civil aviation authority domain pattern — matches the global default norm of free public eAIP access | H124: Phase 2 - Verify | I124: 3 | J124: 1 | K124: Not Started
A125: AFRICA | B125: Kenya | C125: HK | D125: https://eaip.kcaa.or.ke/eAIPHome.aspx | F125: LIKELY FREE (Unverified) | G125: Government / ANSP / civil aviation authority domain pattern — matches the global default norm of free public eAIP access | H125: Phase 2 - Verify | I125: 3 | J125: 1 | K125: Not Started
A126: AFRICA | B126: Lesotho | C126: FX | D126: http://lesothoembassy.de/DCAweb/sections/ais.htm | F126: LIKELY FREE (Unverified) | G126: No paid/restricted signal detected — defaulting to global norm (most state eAIP sites are free to view); not individually confirmed | H126: Phase 2 - Verify | I126: 3 | J126: 1 | K126: Not Started
A127: AFRICA | B127: Libya | C127: HL | D127: http://caa.gov.ly/ais/aip/ad/ | F127: LIKELY FREE (Unverified) | G127: Government / ANSP / civil aviation authority domain pattern — matches the global default norm of free public eAIP access | H127: Phase 2 - Verify | I127: 3 | J127: 1 | K127: Not Started
A128: AFRICA | B128: Malawi | C128: FW | D128: https://sabrenow.sharepoint.com/teams/ACD/FLT/FPM/dataservices/CD AIP Library/Forms/AllItems.aspx?viewid=997f0975-16c6-4799-82e6-f689780367dc&id=%2Fteams%2FACD%2FFLT%2FFPM%2Fdataservices%2FCD%20AIP%20Library%2FMalawi | F128: RESTRICTED / INTERNAL - VERIFY | G128: Cloud file-share link, not an official public AIS domain — likely wrong/internal link | H128: Phase X - Unresolved | I128: 3 | J128: 5 | K128: Not Started
A129: AFRICA | B129: Mauritius | C129: FI | D129: https://civil-aviation.govmu.org/Pages/ANSPUBLICATION.aspx | F129: LIKELY FREE (Unverified) | G129: Government / ANSP / civil aviation authority domain pattern — matches the global default norm of free public eAIP access | H129: Phase 2 - Verify | I129: 3 | J129: 1 | K129: Not Started
A130: AFRICA | B130: Mayotte (France) | C130: FM | D130: https://www.sia.aviation-civile.gouv.fr/documents/htmlshow?f=dvd/eAIP_22_APR_2021/RUN/home.html | F130: FREE (Verified) | G130: Confirmed via direct check of the official AIS/ANSP site | H130: Phase 1 - Free | I130: 3 | J130: 9 | K130: Not Started
A131: AFRICA | B131: Morocco | C131: GM | D131: http://siamaroc.onda.ma/ | F131: LIKELY FREE (Unverified) | G131: No paid/restricted signal detected — defaulting to global norm (most state eAIP sites are free to view); not individually confirmed | H131: Phase 2 - Verify | I131: 3 | J131: 1 | K131: Not Started
A132: AFRICA | B132: Mozambique | C132: FQ | F132: NO SOURCE FOUND | G132: No URL on file — needs research from scratch | H132: Phase X - Unresolved | I132: 3 | J132: 0 | K132: Not Started
...

Sheet Needs Research
B2: Action List — States That Need Manual Research
B3: No source on file, or the link on file looks internal/restricted rather than an official public AIS site.
A5: Region | B5: Country | C5: ICAO Code | D5: Access Type | E5: Issue / URL on File | F5: Suggested Next Step
A6: AFRICA | B6: Botswana | C6: FB | D6: LOGIN REQUIRED - VERIFY | E6: https://www.caab.co.bw/my-account/ | F6: Register/log in once manually to confirm whether access is free or paid before building a connector.
A7: EUROPE | B7: Greece | C7: LG | D7: LOGIN REQUIRED - VERIFY | E7: http://www.ypa.gr/aip/login | F7: Register/log in once manually to confirm whether access is free or paid before building a connector.
A8: NORTH & CENTRAL AMERICA | B8: Jamaica | C8: MK | D8: LOGIN REQUIRED - VERIFY | E8: https://aim.jcaa.aero/client/login | F8: Register/log in once manually to confirm whether access is free or paid before building a connector.
A9: SOUTH AMERICA | B9: Peru | C9: SP | D9: LOGIN REQUIRED - VERIFY | E9: http://extranet.corpac.gob.pe/sso/ | F9: Register/log in once manually to confirm whether access is free or paid before building a connector.
A10: AFRICA | B10: Congo (Kinshasa) | C10: FZ | D10: NO SOURCE FOUND | E10: (none on file) | F10: Search the state's civil aviation authority / ANSP website directly; check the Embry-Riddle "Electronic AIPs by Country" directory or EUROCONTROL's eAIP list as a starting point.
A11: AFRICA | B11: Eswatini | C11: FD | D11: NO SOURCE FOUND | E11: (none on file) | F11: Search the state's civil aviation authority / ANSP website directly; check the Embry-Riddle "Electronic AIPs by Country" directory or EUROCONTROL's eAIP list as a starting point.
A12: AFRICA | B12: Ethiopia | C12: HA | D12: NO SOURCE FOUND | E12: (none on file) | F12: Search the state's civil aviation authority / ANSP website directly; check the Embry-Riddle "Electronic AIPs by Country" directory or EUROCONTROL's eAIP list as a starting point.
A13: AFRICA | B13: Mozambique | C13: FQ | D13: NO SOURCE FOUND | E13: (none on file) | F13: Search the state's civil aviation authority / ANSP website directly; check the Embry-Riddle "Electronic AIPs by Country" directory or EUROCONTROL's eAIP list as a starting point.
A14: SOUTH AMERICA | B14: Guyana | C14: SY | D14: NO SOURCE FOUND | E14: (none on file) | F14: Search the state's civil aviation authority / ANSP website directly; check the Embry-Riddle "Electronic AIPs by Country" directory or EUROCONTROL's eAIP list as a starting point.
A15: AFRICA | B15: Burundi | C15: HB | D15: RESTRICTED / INTERNAL - VERIFY | E15: https://sabrenow.sharepoint.com/teams/ACD/FLT/FPM/dataservices/Test | F15: This looks like an internal file share, not the official public AIS site. Find and substitute the real state AIS URL.
A16: AFRICA | B16: Eritrea | C16: HH | D16: RESTRICTED / INTERNAL - VERIFY | E16: https://sabrenow.sharepoint.com/teams/ACD/FLT/FPM/dataservices/Test/Forms/AllItems.aspx | F16: This looks like an internal file share, not the official public AIS site. Find and substitute the real state AIS URL.
... A21: NORTH & CENTRAL AMERICA | B21: Canada | C21: CY & CZ | D21: RESTRICTED / INTERNAL - VERIFY | E21: https://navcanada.sharepoint.com/sites/Extranet | F21: This looks like an internal file share, not the official public AIS site. Find and substitute the real state AIS URL.
